2023-08-21 13:16:07,636 ERROR: Exception on /course [GET] [in C:\Users\Eliza Lenjani\Desktop\2205FlaskNew\venv\lib\site-packages\flask\app.py:1414]
Traceback (most recent call last):
  File "C:\Users\Eliza Lenjani\Desktop\2205FlaskNew\venv\lib\site-packages\sqlalchemy\engine\base.py", line 1965, in _exec_single_context
    self.dialect.do_execute(
  File "C:\Users\Eliza Lenjani\Desktop\2205FlaskNew\venv\lib\site-packages\sqlalchemy\engine\default.py", line 921, in do_execute
    cursor.execute(statement, parameters)
sqlite3.OperationalError: no such table: courses

The above exception was the direct cause of the following exception:

Traceback (most recent call last):
  File "C:\Users\Eliza Lenjani\Desktop\2205FlaskNew\venv\lib\site-packages\flask\app.py", line 2190, in wsgi_app
    response = self.full_dispatch_request()
  File "C:\Users\Eliza Lenjani\Desktop\2205FlaskNew\venv\lib\site-packages\flask\app.py", line 1486, in full_dispatch_request
    rv = self.handle_user_exception(e)
  File "C:\Users\Eliza Lenjani\Desktop\2205FlaskNew\venv\lib\site-packages\flask\app.py", line 1484, in full_dispatch_request
    rv = self.dispatch_request()
  File "C:\Users\Eliza Lenjani\Desktop\2205FlaskNew\venv\lib\site-packages\flask\app.py", line 1469, in dispatch_request
    return self.ensure_sync(self.view_functions[rule.endpoint])(**view_args)
  File "C:\Users\Eliza Lenjani\Desktop\2205FlaskNew\app\main\routes.py", line 213, in courses
    course_list = Courses.query.all()
  File "C:\Users\Eliza Lenjani\Desktop\2205FlaskNew\venv\lib\site-packages\sqlalchemy\orm\query.py", line 2692, in all
    return self._iter().all()  # type: ignore
  File "C:\Users\Eliza Lenjani\Desktop\2205FlaskNew\venv\lib\site-packages\sqlalchemy\orm\query.py", line 2846, in _iter
    result: Union[ScalarResult[_T], Result[_T]] = self.session.execute(
  File "C:\Users\Eliza Lenjani\Desktop\2205FlaskNew\venv\lib\site-packages\sqlalchemy\orm\session.py", line 2246, in execute
    return self._execute_internal(
  File "C:\Users\Eliza Lenjani\Desktop\2205FlaskNew\venv\lib\site-packages\sqlalchemy\orm\session.py", line 2141, in _execute_internal
    result: Result[Any] = compile_state_cls.orm_execute_statement(
  File "C:\Users\Eliza Lenjani\Desktop\2205FlaskNew\venv\lib\site-packages\sqlalchemy\orm\context.py", line 293, in orm_execute_statement
    result = conn.execute(
  File "C:\Users\Eliza Lenjani\Desktop\2205FlaskNew\venv\lib\site-packages\sqlalchemy\engine\base.py", line 1412, in execute
    return meth(
  File "C:\Users\Eliza Lenjani\Desktop\2205FlaskNew\venv\lib\site-packages\sqlalchemy\sql\elements.py", line 483, in _execute_on_connection
    return connection._execute_clauseelement(
  File "C:\Users\Eliza Lenjani\Desktop\2205FlaskNew\venv\lib\site-packages\sqlalchemy\engine\base.py", line 1635, in _execute_clauseelement
    ret = self._execute_context(
  File "C:\Users\Eliza Lenjani\Desktop\2205FlaskNew\venv\lib\site-packages\sqlalchemy\engine\base.py", line 1844, in _execute_context
    return self._exec_single_context(
  File "C:\Users\Eliza Lenjani\Desktop\2205FlaskNew\venv\lib\site-packages\sqlalchemy\engine\base.py", line 1984, in _exec_single_context
    self._handle_dbapi_exception(
  File "C:\Users\Eliza Lenjani\Desktop\2205FlaskNew\venv\lib\site-packages\sqlalchemy\engine\base.py", line 2339, in _handle_dbapi_exception
    raise sqlalchemy_exception.with_traceback(exc_info[2]) from e
  File "C:\Users\Eliza Lenjani\Desktop\2205FlaskNew\venv\lib\site-packages\sqlalchemy\engine\base.py", line 1965, in _exec_single_context
    self.dialect.do_execute(
  File "C:\Users\Eliza Lenjani\Desktop\2205FlaskNew\venv\lib\site-packages\sqlalchemy\engine\default.py", line 921, in do_execute
    cursor.execute(statement, parameters)
sqlalchemy.exc.OperationalError: (sqlite3.OperationalError) no such table: courses
[SQL: SELECT courses.id AS courses_id, courses.course_title AS courses_course_title, courses.course_leader AS courses_course_leader, courses.start_date AS courses_start_date, courses.end_date AS courses_end_date, courses.venue_name_address AS courses_venue_name_address, courses.contact_phone AS courses_contact_phone, courses.contact_email AS courses_contact_email, courses.description AS courses_description 
FROM courses]
(Background on this error at: https://sqlalche.me/e/20/e3q8)
2023-08-21 13:20:32,379 ERROR: Exception on /course [GET] [in C:\Users\Eliza Lenjani\Desktop\2205FlaskNew\venv\lib\site-packages\flask\app.py:1414]
Traceback (most recent call last):
  File "C:\Users\Eliza Lenjani\Desktop\2205FlaskNew\venv\lib\site-packages\sqlalchemy\engine\base.py", line 1965, in _exec_single_context
    self.dialect.do_execute(
  File "C:\Users\Eliza Lenjani\Desktop\2205FlaskNew\venv\lib\site-packages\sqlalchemy\engine\default.py", line 921, in do_execute
    cursor.execute(statement, parameters)
sqlite3.OperationalError: no such table: courses

The above exception was the direct cause of the following exception:

Traceback (most recent call last):
  File "C:\Users\Eliza Lenjani\Desktop\2205FlaskNew\venv\lib\site-packages\flask\app.py", line 2190, in wsgi_app
    response = self.full_dispatch_request()
  File "C:\Users\Eliza Lenjani\Desktop\2205FlaskNew\venv\lib\site-packages\flask\app.py", line 1486, in full_dispatch_request
    rv = self.handle_user_exception(e)
  File "C:\Users\Eliza Lenjani\Desktop\2205FlaskNew\venv\lib\site-packages\flask\app.py", line 1484, in full_dispatch_request
    rv = self.dispatch_request()
  File "C:\Users\Eliza Lenjani\Desktop\2205FlaskNew\venv\lib\site-packages\flask\app.py", line 1469, in dispatch_request
    return self.ensure_sync(self.view_functions[rule.endpoint])(**view_args)
  File "C:\Users\Eliza Lenjani\Desktop\2205FlaskNew\app\main\routes.py", line 213, in courses
    course_list = Courses.query.all()
  File "C:\Users\Eliza Lenjani\Desktop\2205FlaskNew\venv\lib\site-packages\sqlalchemy\orm\query.py", line 2692, in all
    return self._iter().all()  # type: ignore
  File "C:\Users\Eliza Lenjani\Desktop\2205FlaskNew\venv\lib\site-packages\sqlalchemy\orm\query.py", line 2846, in _iter
    result: Union[ScalarResult[_T], Result[_T]] = self.session.execute(
  File "C:\Users\Eliza Lenjani\Desktop\2205FlaskNew\venv\lib\site-packages\sqlalchemy\orm\session.py", line 2246, in execute
    return self._execute_internal(
  File "C:\Users\Eliza Lenjani\Desktop\2205FlaskNew\venv\lib\site-packages\sqlalchemy\orm\session.py", line 2141, in _execute_internal
    result: Result[Any] = compile_state_cls.orm_execute_statement(
  File "C:\Users\Eliza Lenjani\Desktop\2205FlaskNew\venv\lib\site-packages\sqlalchemy\orm\context.py", line 293, in orm_execute_statement
    result = conn.execute(
  File "C:\Users\Eliza Lenjani\Desktop\2205FlaskNew\venv\lib\site-packages\sqlalchemy\engine\base.py", line 1412, in execute
    return meth(
  File "C:\Users\Eliza Lenjani\Desktop\2205FlaskNew\venv\lib\site-packages\sqlalchemy\sql\elements.py", line 483, in _execute_on_connection
    return connection._execute_clauseelement(
  File "C:\Users\Eliza Lenjani\Desktop\2205FlaskNew\venv\lib\site-packages\sqlalchemy\engine\base.py", line 1635, in _execute_clauseelement
    ret = self._execute_context(
  File "C:\Users\Eliza Lenjani\Desktop\2205FlaskNew\venv\lib\site-packages\sqlalchemy\engine\base.py", line 1844, in _execute_context
    return self._exec_single_context(
  File "C:\Users\Eliza Lenjani\Desktop\2205FlaskNew\venv\lib\site-packages\sqlalchemy\engine\base.py", line 1984, in _exec_single_context
    self._handle_dbapi_exception(
  File "C:\Users\Eliza Lenjani\Desktop\2205FlaskNew\venv\lib\site-packages\sqlalchemy\engine\base.py", line 2339, in _handle_dbapi_exception
    raise sqlalchemy_exception.with_traceback(exc_info[2]) from e
  File "C:\Users\Eliza Lenjani\Desktop\2205FlaskNew\venv\lib\site-packages\sqlalchemy\engine\base.py", line 1965, in _exec_single_context
    self.dialect.do_execute(
  File "C:\Users\Eliza Lenjani\Desktop\2205FlaskNew\venv\lib\site-packages\sqlalchemy\engine\default.py", line 921, in do_execute
    cursor.execute(statement, parameters)
sqlalchemy.exc.OperationalError: (sqlite3.OperationalError) no such table: courses
[SQL: SELECT courses.id AS courses_id, courses.course_title AS courses_course_title, courses.course_leader AS courses_course_leader, courses.start_date AS courses_start_date, courses.end_date AS courses_end_date, courses.venue_name_address AS courses_venue_name_address, courses.contact_phone AS courses_contact_phone, courses.contact_email AS courses_contact_email, courses.description AS courses_description 
FROM courses]
(Background on this error at: https://sqlalche.me/e/20/e3q8)
